# Snapshot report for `test/log.js`

The actual snapshot is saved in `log.js.snap`.

Generated by [AVA](https://ava.li).

## [multipleResolves] should fire opts.log() with arguments

> Snapshot 1

    [
      `[32m[7m[1m i  multipleResolves [3m(a promise was  multiple times)[23m [22m[27m[39m‚êä
      [32mInitially resolved with: { success: true }[39m‚êä
      [32mThen rejected with: Error: message[39m‚êä
      [2m    at STACK TRACE[22m`,
      `MultipleResolves: a promise was resolved/rejected multiple times:‚êä
      Initially resolved with: { success: true }‚êä
      Then rejected with: Error: message‚êä
          at STACK TRACE`,
      `MultipleResolves: a promise was resolved/rejected multiple times:‚êä
      Initially resolved with: { success: true }‚êä
      Then rejected with: Error: message`,
      'info',
      {
        name: 'multipleResolves',
        nextRejected: true,
        nextValue: Error {
          message: 'message',
        },
        rejected: false,
        value: {
          success: true,
        },
      },
    ]

## [rejectionHandled] should fire opts.log() with arguments

> Snapshot 1

    [
      `[31m[7m[1m √ó  rejectionHandled [3m(a promise was rejected and handled too late)[23m [22m[27m Error: message[39m‚êä
      [2m    at STACK TRACE[22m`,
      `RejectionHandled: a promise was rejected and handled too late: Error: message‚êä
          at STACK TRACE`,
      'RejectionHandled: a promise was rejected and handled too late: Error: message',
      'error',
      {
        name: 'rejectionHandled',
        value: Error {
          message: 'message',
        },
      },
    ]

## [uncaughtException] should fire opts.log() with arguments

> Snapshot 1

    [
      `[31m[7m[1m √ó  uncaughtException [3m(an exception was thrown but not caught)[23m [22m[27m Error: message[39m‚êä
      [2m    at STACK TRACE[22m`,
      `UncaughtException: an exception was thrown but not caught: Error: message‚êä
          at STACK TRACE`,
      'UncaughtException: an exception was thrown but not caught: Error: message',
      'error',
      {
        name: 'uncaughtException',
        value: Error {
          message: 'message',
        },
      },
    ]

## [unhandledRejection] should fire opts.log() with arguments

> Snapshot 1

    [
      `[31m[7m[1m √ó  unhandledRejection [3m(a promise was rejected but not handled)[23m [22m[27m Error: message[39m‚êä
      [2m    at STACK TRACE[22m`,
      `UnhandledRejection: a promise was rejected but not handled: Error: message‚êä
          at STACK TRACE`,
      'UnhandledRejection: a promise was rejected but not handled: Error: message',
      'error',
      {
        name: 'unhandledRejection',
        value: Error {
          message: 'message',
        },
      },
    ]

## [warning] should fire opts.log() with arguments

> Snapshot 1

    [
      `[33m[7m[1m ‚Äº  warning [3m(WarningType)[23m [22m[27m message[39m‚êä
      [33m[500] Detail[39m‚êä
      [2m    at STACK TRACE[22m`,
      `Warning: WarningType: message‚êä
      [500] Detail‚êä
          at STACK TRACE`,
      `Warning: WarningType: message‚êä
      [500] Detail`,
      'warn',
      {
        name: 'warning',
        value: WarningType (Error) {
          code: '500',
          detail: 'Detail',
          message: 'message',
        },
      },
    ]
